<?xml version="1.0"?>
<robot name="rover">
  <link name="base_link">
    <visual>
      <geometry>
        <box size="0.7 0.5 0.3"/>
      </geometry>
      <material name="black"/>
    </visual>
    <collision>
      <geometry>
        <box size="0.5 0.3 0.2"/>
      </geometry>
    </collision>
    <inertial>
      <mass value="1.0"/>
      <inertia ixx="0.01" ixy="0.0" ixz="0.0" iyy="0.01" iyz="0.0" izz="0.01"/>
    </inertial>
  </link>

  <left_joint>left_wheel_joint</left_joint>
  <right_joint>right_wheel_joint</right_joint>
  <joint name="left_wheel_joint" type="continuous">
    <parent link="base_link"/>
    <child link="left_wheel"/>
    <origin xyz="0.5 0.3 0.0" rpy="0 0 0"/>
    <axis xyz="0 1 0"/>
  </joint>
  <joint name="right_wheel_joint" type="continuous">
    <parent link="base_link"/>
    <child link="right_wheel"/>
    <origin xyz="0.5 0.3 0.0" rpy="0 0 0"/>
    <axis xyz="0 1 0"/>
  </joint>
  
  <wheel_separation>0.50</wheel_separation>
  <wheel_diameter>0.2</wheel_diameter>
  
</robot>
